Workbook

Sheet DATA
A1: user | B1: date_entry | C1: Week_No | D1: Flag_loyalusers
A2: 380320 | B2: 45030 | C2: =_xlfn.ISOWEEKNUM(B2) -> 15 | D2: =IFERROR(VLOOKUP(A2,'Лояльные пользователи'!$A$2:$C$2731,3,0),0) -> 0
A3: 379442 | B3: 44979 | C3: =_xlfn.ISOWEEKNUM(B3) -> 8 | D3: =IFERROR(VLOOKUP(A3,'Лояльные пользователи'!$A$2:$C$2731,3,0),0) -> 1
A4: 378395 | B4: 45036 | C4: =_xlfn.ISOWEEKNUM(B4) -> 16 | D4: =IFERROR(VLOOKUP(A4,'Лояльные пользователи'!$A$2:$C$2731,3,0),0) -> 1
A5: 379971 | B5: 45033 | C5: =_xlfn.ISOWEEKNUM(B5) -> 16 | D5: =IFERROR(VLOOKUP(A5,'Лояльные пользователи'!$A$2:$C$2731,3,0),0) -> 1
A6: 378568 | B6: 45007 | C6: =_xlfn.ISOWEEKNUM(B6) -> 12 | D6: =IFERROR(VLOOKUP(A6,'Лояльные пользователи'!$A$2:$C$2731,3,0),0) -> 1
A7: 378377 | B7: 44962 | C7: =_xlfn.ISOWEEKNUM(B7) -> 5 | D7: =IFERROR(VLOOKUP(A7,'Лояльные пользователи'!$A$2:$C$2731,3,0),0) -> 1
A8: 379256 | B8: 44963 | C8: =_xlfn.ISOWEEKNUM(B8) -> 6 | D8: =IFERROR(VLOOKUP(A8,'Лояльные пользователи'!$A$2:$C$2731,3,0),0) -> 1
A9: 379196 | B9: 45040 | C9: =_xlfn.ISOWEEKNUM(B9) -> 17 | D9: =IFERROR(VLOOKUP(A9,'Лояльные пользователи'!$A$2:$C$2731,3,0),0) -> 1
A10: 381623 | B10: 45022 | C10: =_xlfn.ISOWEEKNUM(B10) -> 14 | D10: =IFERROR(VLOOKUP(A10,'Лояльные пользователи'!$A$2:$C$2731,3,0),0) -> 1
A11: 381934 | B11: 44994 | C11: =_xlfn.ISOWEEKNUM(B11) -> 10 | D11: =IFERROR(VLOOKUP(A11,'Лояльные пользователи'!$A$2:$C$2731,3,0),0) -> 0
A12: 378392 | B12: 44973 | C12: =_xlfn.ISOWEEKNUM(B12) -> 7 | D12: =IFERROR(VLOOKUP(A12,'Лояльные пользователи'!$A$2:$C$2731,3,0),0) -> 1
A13: 381482 | B13: 45039 | C13: =_xlfn.ISOWEEKNUM(B13) -> 16 | D13: =IFERROR(VLOOKUP(A13,'Лояльные пользователи'!$A$2:$C$2731,3,0),0) -> 1
... A16360: 380062 | B16360: 45011 | C16360: =_xlfn.ISOWEEKNUM(B16360) -> 12 | D16360: =IFERROR(VLOOKUP(A16360,'Лояльные пользователи'!$A$2:$C$2731,3,0),0) -> 1

Sheet users
A1: user | B1: flag_install
A2: 381146 | B2: 0
A3: 381942 | B3: 1
A4: 379900 | B4: 1
A5: 381880 | B5: 1
A6: 378425 | B6: 1
A7: 379587 | B7: 0
A8: 380655 | B8: 1
A9: 378621 | B9: 1
A10: 378679 | B10: 1
A11: 379304 | B11: 1
A12: 381739 | B12: 1
A13: 381219 | B13: 1
... A15902: 381543 | B15902: 0

Sheet DauWauMau
F1: Week | G1: Date | H1: DAU | I1: WAU | J1: MAU | K1: SF(week) | L1: SF(month)
A2: Названия строк | B2: Число разных элементов в столбце user | F2: =_xlfn.ISOWEEKNUM(G2) -> 5 | G2: 1-фев | H2: 170 | I2: =VLOOKUP(F2,$A$9:$B$21,2,0) -> 675 | J2: 2622 | K2: =H2/I2 -> 0.25185185 | L2: =H2/J2 -> 0.064836003
A3: фев | B3: 2622 | F3: =_xlfn.ISOWEEKNUM(G3) -> 6 | G3: 2-фев | H3: 138 | I3: =VLOOKUP(F3,$A$9:$B$21,2,0) -> 949 | J3: 2622 | K3: =H3/I3 -> 0.14541623 | L3: =H3/J3 -> 0.052631579
A4: мар | B4: 2813 | F4: =_xlfn.ISOWEEKNUM(G4) -> 6 | G4: 3-фев | H4: 130 | I4: =VLOOKUP(F4,$A$9:$B$21,2,0) -> 949 | J4: 2622 | K4: =H4/I4 -> 0.1369863 | L4: =H4/J4 -> 0.049580473
A5: апр | B5: 3485 | F5: =_xlfn.ISOWEEKNUM(G5) -> 6 | G5: 4-фев | H5: 139 | I5: =VLOOKUP(F5,$A$9:$B$21,2,0) -> 949 | J5: 2622 | K5: =H5/I5 -> 0.14646997 | L5: =H5/J5 -> 0.053012967
A6: Общий итог | B6: 3943 | F6: =_xlfn.ISOWEEKNUM(G6) -> 6 | G6: 5-фев | H6: 147 | I6: =VLOOKUP(F6,$A$9:$B$21,2,0) -> 949 | J6: 2622 | K6: =H6/I6 -> 0.15489989 | L6: =H6/J6 -> 0.056064073
F7: =_xlfn.ISOWEEKNUM(G7) -> 6 | G7: 6-фев | H7: 154 | I7: =VLOOKUP(F7,$A$9:$B$21,2,0) -> 949 | J7: 2622 | K7: =H7/I7 -> 0.16227608 | L7: =H7/J7 -> 0.058733791
A8: Названия строк | B8: Число разных элементов в столбце user | F8: =_xlfn.ISOWEEKNUM(G8) -> 6 | G8: 7-фев | H8: 155 | I8: =VLOOKUP(F8,$A$9:$B$21,2,0) -> 949 | J8: 2622 | K8: =H8/I8 -> 0.16332982 | L8: =H8/J8 -> 0.059115179
A9: 5 | B9: 675 | F9: =_xlfn.ISOWEEKNUM(G9) -> 6 | G9: 8-фев | H9: 145 | I9: =VLOOKUP(F9,$A$9:$B$21,2,0) -> 949 | J9: 2622 | K9: =H9/I9 -> 0.15279241 | L9: =H9/J9 -> 0.055301297
A10: 6 | B10: 949 | F10: =_xlfn.ISOWEEKNUM(G10) -> 7 | G10: 9-фев | H10: 148 | I10: =VLOOKUP(F10,$A$9:$B$21,2,0) -> 869 | J10: 2622 | K10: =H10/I10 -> 0.1703107 | L10: =H10/J10 -> 0.056445461
A11: 7 | B11: 869 | F11: =_xlfn.ISOWEEKNUM(G11) -> 7 | G11: 10-фев | H11: 169 | I11: =VLOOKUP(F11,$A$9:$B$21,2,0) -> 869 | J11: 2622 | K11: =H11/I11 -> 0.19447641 | L11: =H11/J11 -> 0.064454615
A12: 8 | B12: 923 | F12: =_xlfn.ISOWEEKNUM(G12) -> 7 | G12: 11-фев | H12: 141 | I12: =VLOOKUP(F12,$A$9:$B$21,2,0) -> 869 | J12: 2622 | K12: =H12/I12 -> 0.16225547 | L12: =H12/J12 -> 0.053775744
A13: 9 | B13: 896 | F13: =_xlfn.ISOWEEKNUM(G13) -> 7 | G13: 12-фев | H13: 137 | I13: =VLOOKUP(F13,$A$9:$B$21,2,0) -> 869 | J13: 2622 | K13: =H13/I13 -> 0.15765247 | L13: =H13/J13 -> 0.052250191
A14: 10 | B14: 936 | F14: =_xlfn.ISOWEEKNUM(G14) -> 7 | G14: 13-фев | H14: 141 | I14: =VLOOKUP(F14,$A$9:$B$21,2,0) -> 869 | J14: 2622 | K14: =H14/I14 -> 0.16225547 | L14: =H14/J14 -> 0.053775744
A15: 11 | B15: 914 | F15: =_xlfn.ISOWEEKNUM(G15) -> 7 | G15: 14-фев | H15: 123 | I15: =VLOOKUP(F15,$A$9:$B$21,2,0) -> 869 | J15: 2622 | K15: =H15/I15 -> 0.141542 | L15: =H15/J15 -> 0.046910755
A16: 12 | B16: 908 | F16: =_xlfn.ISOWEEKNUM(G16) -> 7 | G16: 15-фев | H16: 154 | I16: =VLOOKUP(F16,$A$9:$B$21,2,0) -> 869 | J16: 2622 | K16: =H16/I16 -> 0.17721519 | L16: =H16/J16 -> 0.058733791
A17: 13 | B17: 915 | F17: =_xlfn.ISOWEEKNUM(G17) -> 8 | G17: 16-фев | H17: 149 | I17: =VLOOKUP(F17,$A$9:$B$21,2,0) -> 923 | J17: 2622 | K17: =H17/I17 -> 0.16143012 | L17: =H17/J17 -> 0.05682685
A18: 14 | B18: 1426 | F18: =_xlfn.ISOWEEKNUM(G18) -> 8 | G18: 17-фев | H18: 128 | I18: =VLOOKUP(F18,$A$9:$B$21,2,0) -> 923 | J18: 2622 | K18: =H18/I18 -> 0.13867822 | L18: =H18/J18 -> 0.048817696
A19: 15 | B19: 1723 | F19: =_xlfn.ISOWEEKNUM(G19) -> 8 | G19: 18-фев | H19: 133 | I19: =VLOOKUP(F19,$A$9:$B$21,2,0) -> 923 | J19: 2622 | K19: =H19/I19 -> 0.14409534 | L19: =H19/J19 -> 0.050724638
A20: 16 | B20: 1694 | F20: =_xlfn.ISOWEEKNUM(G20) -> 8 | G20: 19-фев | H20: 135 | I20: =VLOOKUP(F20,$A$9:$B$21,2,0) -> 923 | J20: 2622 | K20: =H20/I20 -> 0.14626219 | L20: =H20/J20 -> 0.051487414
A21: 17 | B21: 1164 | F21: =_xlfn.ISOWEEKNUM(G21) -> 8 | G21: 20-фев | H21: 154 | I21: =VLOOKUP(F21,$A$9:$B$21,2,0) -> 923 | J21: 2622 | K21: =H21/I21 -> 0.16684724 | L21: =H21/J21 -> 0.058733791
A22: Общий итог | B22: 3943 | F22: =_xlfn.ISOWEEKNUM(G22) -> 8 | G22: 21-фев | H22: 134 | I22: =VLOOKUP(F22,$A$9:$B$21,2,0) -> 923 | J22: 2622 | K22: =H22/I22 -> 0.14517876 | L22: =H22/J22 -> 0.051106026
F23: =_xlfn.ISOWEEKNUM(G23) -> 8 | G23: 22-фев | H23: 163 | I23: =VLOOKUP(F23,$A$9:$B$21,2,0) -> 923 | J23: 2622 | K23: =H23/I23 -> 0.17659805 | L23: =H23/J23 -> 0.062166285
A24: Названия строк | B24: Число разных элементов в столбце user | F24: =_xlfn.ISOWEEKNUM(G24) -> 9 | G24: 23-фев | H24: 145 | I24: =VLOOKUP(F24,$A$9:$B$21,2,0) -> 896 | J24: 2622 | K24: =H24/I24 -> 0.16183036 | L24: =H24/J24 -> 0.055301297
A25: 1-фев | B25: 170 | F25: =_xlfn.ISOWEEKNUM(G25) -> 9 | G25: 24-фев | H25: 138 | I25: =VLOOKUP(F25,$A$9:$B$21,2,0) -> 896 | J25: 2622 | K25: =H25/I25 -> 0.15401786 | L25: =H25/J25 -> 0.052631579
A26: 2-фев | B26: 138 | F26: =_xlfn.ISOWEEKNUM(G26) -> 9 | G26: 25-фев | H26: 140 | I26: =VLOOKUP(F26,$A$9:$B$21,2,0) -> 896 | J26: 2622 | K26: =H26/I26 -> 0.15625 | L26: =H26/J26 -> 0.053394355
A27: 3-фев | B27: 130 | F27: =_xlfn.ISOWEEKNUM(G27) -> 9 | G27: 26-фев | H27: 139 | I27: =VLOOKUP(F27,$A$9:$B$21,2,0) -> 896 | J27: 2622 | K27: =H27/I27 -> 0.15513393 | L27: =H27/J27 -> 0.053012967
A28: 4-фев | B28: 139 | F28: =_xlfn.ISOWEEKNUM(G28) -> 9 | G28: 27-фев | H28: 137 | I28: =VLOOKUP(F28,$A$9:$B$21,2,0) -> 896 | J28: 2622 | K28: =H28/I28 -> 0.15290179 | L28: =H28/J28 -> 0.052250191
A29: 5-фев | B29: 147 | F29: =_xlfn.ISOWEEKNUM(G29) -> 9 | G29: 28-фев | H29: 129 | I29: =VLOOKUP(F29,$A$9:$B$21,2,0) -> 896 | J29: 2622 | K29: =H29/I29 -> 0.14397321 | L29: =H29/J29 -> 0.049199085
A30: 6-фев | B30: 154 | F30: =_xlfn.ISOWEEKNUM(G30) -> 9 | G30: 1-мар | H30: 149 | I30: =VLOOKUP(F30,$A$9:$B$21,2,0) -> 896 | J30: 2813 | K30: =H30/I30 -> 0.16629464 | L30: =H30/J30 -> 0.052968361
A31: 7-фев | B31: 155 | F31: =_xlfn.ISOWEEKNUM(G31) -> 10 | G31: 2-мар | H31: 154 | I31: =VLOOKUP(F31,$A$9:$B$21,2,0) -> 936 | J31: 2813 | K31: =H31/I31 -> 0.16452991 | L31: =H31/J31 -> 0.054745823
A32: 8-фев | B32: 145 | F32: =_xlfn.ISOWEEKNUM(G32) -> 10 | G32: 3-мар | H32: 141 | I32: =VLOOKUP(F32,$A$9:$B$21,2,0) -> 936 | J32: 2813 | K32: =H32/I32 -> 0.15064103 | L32: =H32/J32 -> 0.050124422
A33: 9-фев | B33: 148 | F33: =_xlfn.ISOWEEKNUM(G33) -> 10 | G33: 4-мар | H33: 134 | I33: =VLOOKUP(F33,$A$9:$B$21,2,0) -> 936 | J33: 2813 | K33: =H33/I33 -> 0.14316239 | L33: =H33/J33 -> 0.047635976
A34: 10-фев | B34: 169 | F34: =_xlfn.ISOWEEKNUM(G34) -> 10 | G34: 5-мар | H34: 123 | I34: =VLOOKUP(F34,$A$9:$B$21,2,0) -> 936 | J34: 2813 | K34: =H34/I34 -> 0.13141026 | L34: =H34/J34 -> 0.04372556
A35: 11-фев | B35: 141 | F35: =_xlfn.ISOWEEKNUM(G35) -> 10 | G35: 6-мар | H35: 131 | I35: =VLOOKUP(F35,$A$9:$B$21,2,0) -> 936 | J35: 2813 | K35: =H35/I35 -> 0.13995726 | L35: =H35/J35 -> 0.046569499
A36: 12-фев | B36: 137 | F36: =_xlfn.ISOWEEKNUM(G36) -> 10 | G36: 7-мар | H36: 149 | I36: =VLOOKUP(F36,$A$9:$B$21,2,0) -> 936 | J36: 2813 | K36: =H36/I36 -> 0.15918803 | L36: =H36/J36 -> 0.052968361
... A88: 5-апр | B88: 155 | F88: =_xlfn.ISOWEEKNUM(G88) -> 18 | G88: 28-апр | H88: 142 | I88: =VLOOKUP(F88,$A$9:$B$21,2,0) -> #N/A | J88: 3485 | K88: =H88/I88 -> #N/A | L88: =H88/J88 -> 0.040746055
A89: 6-апр | B89: 300
A90: 7-апр | B90: 292
A91: 8-апр | B91: 317
...

Sheet K-factor 
A1: Среднее кол-во приглашений на пользователя | B1: =B5/B4 -> 4.0327162
A2: Вероятность регистрации | B2: =B6/B5 -> 0.67209609
A3: K-factor | B3: =B1*B2 -> 2.7103728
A4: Каличество уникальных пользователей | B4: 3943
A5: Каличество приглашений | B5: 15901
A6: Установок | B6: 10687
A8: Названия строк
A9: 378191
A10: 378192
A11: 378193
A12: 378194
A13: 378195
A14: 378196
A15: 378197
A16: 378198
A17: 378199
A18: 378200
A19: 378201
A20: 378202
... A3951: 382133
A3952: Общий итог

Sheet Лояльные пользователи
A2: Названия строк | B2: Число элементов в столбце user | C2: Flag_loyalusers | E2: Каличество заходов лояльных пользователей
A3: 378192 | B3: 3 | C3: =IF(B3>=3,1,0) -> 1 | E3: =SUM(C3:C2731) -> 2692
A4: 378193 | B4: 3 | C4: =IF(B4>=3,1,0) -> 1
A5: 378194 | B5: 6 | C5: =IF(B5>=3,1,0) -> 1
A6: 378197 | B6: 4 | C6: =IF(B6>=3,1,0) -> 1
A7: 378199 | B7: 6 | C7: =IF(B7>=3,1,0) -> 1
A8: 378200 | B8: 4 | C8: =IF(B8>=3,1,0) -> 1
A9: 378203 | B9: 4 | C9: =IF(B9>=3,1,0) -> 1
A10: 378204 | B10: 3 | C10: =IF(B10>=3,1,0) -> 1
A11: 378205 | B11: 4 | C11: =IF(B11>=3,1,0) -> 1
A12: 378206 | B12: 4 | C12: =IF(B12>=3,1,0) -> 1
A13: 378207 | B13: 4 | C13: =IF(B13>=3,1,0) -> 1
A14: 378210 | B14: 4 | C14: =IF(B14>=3,1,0) -> 1
A15: 378211 | B15: 3 | C15: =IF(B15>=3,1,0) -> 1
... A2731: 382133 | B2731: 16 | C2731: =IF(B2731>=3,1,0) -> 1
A2732: Общий итог | B2732: 15901
A2733: Flag_loyalusers | B2733: 1
A2735: Названия строк | B2735: Число разных элементов в столбце user
A2736: фев | B2736: 205
A2737: мар | B2737: 208
A2738: апр | B2738: 370
A2739: Общий итог | B2739: 702
A2741: Flag_loyalusers | B2741: 1
E2742: Week | F2742: Date | G2742: Dau | H2742: Wau | I2742: Mau
A2743: Названия строк | B2743: Число разных элементов в столбце user | E2743: =_xlfn.ISOWEEKNUM(F2743) -> 5 | F2743: 1-фев | G2743: 9 | H2743: =VLOOKUP(E2743,$A$2838:$B$2850,2,0) -> 38 | I2743: 205
A2744: 1-фев | B2744: 9 | E2744: =_xlfn.ISOWEEKNUM(F2744) -> 6 | F2744: 2-фев | G2744: 5 | H2744: =VLOOKUP(E2744,$A$2838:$B$2850,2,0) -> 58 | I2744: 205
A2745: 2-фев | B2745: 5 | E2745: =_xlfn.ISOWEEKNUM(F2745) -> 6 | F2745: 3-фев | G2745: 6 | H2745: =VLOOKUP(E2745,$A$2838:$B$2850,2,0) -> 58 | I2745: 205
A2746: 3-фев | B2746: 6 | E2746: =_xlfn.ISOWEEKNUM(F2746) -> 6 | F2746: 4-фев | G2746: 11 | H2746: =VLOOKUP(E2746,$A$2838:$B$2850,2,0) -> 58 | I2746: 205
A2747: 4-фев | B2747: 11 | E2747: =_xlfn.ISOWEEKNUM(F2747) -> 6 | F2747: 5-фев | G2747: 7 | H2747: =VLOOKUP(E2747,$A$2838:$B$2850,2,0) -> 58 | I2747: 205
A2748: 5-фев | B2748: 7 | E2748: =_xlfn.ISOWEEKNUM(F2748) -> 6 | F2748: 6-фев | G2748: 10 | H2748: =VLOOKUP(E2748,$A$2838:$B$2850,2,0) -> 58 | I2748: 205
A2749: 6-фев | B2749: 10 | E2749: =_xlfn.ISOWEEKNUM(F2749) -> 6 | F2749: 7-фев | G2749: 9 | H2749: =VLOOKUP(E2749,$A$2838:$B$2850,2,0) -> 58 | I2749: 205
A2750: 7-фев | B2750: 9 | E2750: =_xlfn.ISOWEEKNUM(F2750) -> 6 | F2750: 8-фев | G2750: 7 | H2750: =VLOOKUP(E2750,$A$2838:$B$2850,2,0) -> 58 | I2750: 205
A2751: 8-фев | B2751: 7 | E2751: =_xlfn.ISOWEEKNUM(F2751) -> 7 | F2751: 9-фев | G2751: 9 | H2751: =VLOOKUP(E2751,$A$2838:$B$2850,2,0) -> 52 | I2751: 205
A2752: 9-фев | B2752: 9 | E2752: =_xlfn.ISOWEEKNUM(F2752) -> 7 | F2752: 10-фев | G2752: 7 | H2752: =VLOOKUP(E2752,$A$2838:$B$2850,2,0) -> 52 | I2752: 205
A2753: 10-фев | B2753: 7 | E2753: =_xlfn.ISOWEEKNUM(F2753) -> 7 | F2753: 11-фев | G2753: 8 | H2753: =VLOOKUP(E2753,$A$2838:$B$2850,2,0) -> 52 | I2753: 205
A2754: 11-фев | B2754: 8 | E2754: =_xlfn.ISOWEEKNUM(F2754) -> 7 | F2754: 12-фев | G2754: 9 | H2754: =VLOOKUP(E2754,$A$2838:$B$2850,2,0) -> 52 | I2754: 205
A2755: 12-фев | B2755: 9 | E2755: =_xlfn.ISOWEEKNUM(F2755) -> 7 | F2755: 13-фев | G2755: 7 | H2755: =VLOOKUP(E2755,$A$2838:$B$2850,2,0) -> 52 | I2755: 205
... A2829: 27-апр | B2829: 6 | E2829: =_xlfn.ISOWEEKNUM(F2829) -> 18 | F2829: 28-апр | G2829: 8 | H2829: =VLOOKUP(E2829,$A$2838:$B$2850,2,0) -> #N/A | I2829: 370
A2830: 28-апр | B2830: 8
A2831: 29-апр | B2831: 10
...
